Workbook

Sheet PANDUAN
A1: PANDUAN PENGISIAN DATA — FLEET MAINTENANCE PLANNER (REGION KALIMANTAN)
A3: Template ini KHUSUS untuk REGION KALIMANTAN.
A4: Sheet 'DATA UNIT' SUDAH TERISI OTOMATIS dari data Register Kendaraan resmi PT NAJ (133 unit).
A5: TIDAK PERLU mengetik ulang data unit — kolom hijau adalah data yang sudah benar dari sumber resmi.
A7: TUGAS ADMIN SEKARANG:
A9: 1. Cek sheet 'DATA UNIT' — kalau ada unit di region ini yang TERLEWAT (belum ada di daftar),
A10: boleh ditambahkan manual di baris kosong paling bawah, isi Site/Plat/Tipe/Kategori/Customer.
A12: 2. Buka sheet 'SETUP AWAL ITEM' — kolom 'Plat Nomor' dan 'Nama Item' SUDAH OTOMATIS TERISI
A13: (jangan diketik manual, jangan diubah).
A14: Isi kolom kuning 'Kapan Terakhir Diganti' (tanggal) untuk tiap item, per unit.
A15: Kolom 'KM Saat Diganti' BOLEH DIKOSONGKAN kalau tidak ada catatan pastinya.
A16: Kalau item BELUM PERNAH diganti sejak unit ini dipakai, KOSONGKAN kedua kolom kuning itu.
... A26: - JANGAN mengubah urutan baris di sheet 'SETUP AWAL ITEM'.

Sheet _ItemList
A1: PM Check / Reguler Services
A2: Service A
A3: Service B
A4: Brake Pad
A5: Brake Shoe
A6: Accu
A7: Kampas Kopling Set
A8: Wiper Blade
A9: Ban Depan
A10: Ban Belakang
A11: Ban Serep
A12: Greasing
... A20: Flushing Rem

Sheet DATA UNIT
A1: Site | B1: Plat Nomor | C1: Tipe/Merk Unit | D1: Kategori Kendaraan | E1: Customer | F1: Plat Lama (jika ada)
A2: BPN | B2: B 2444 UIL | C2: Toyota Kijang Innova Zenix 2,0G CVT | D2: pickup_suv | E2: PT. KMSI | F2: KT 1077 WK
A3: BPN | B3: B 2533 UIY | C3: Toyota Kijang Innova Zenix 2,0G CVT | D3: pickup_suv | E3: PT. KMSI | F3: KT 1148 WI
A4: BPN | B4: KT 8404 YR | C4: Toyota All New Hilux 2,4G DC 4X4 M | D4: pickup_suv | E4: PT. UT
A5: BPN | B5: KT 8620 YR | C5: Toyota All New Hilux 2,4G DC 4X4 M | D5: pickup_suv | E5: PT. UT
A6: BPN | B6: KT 8619 YR | C6: Toyota All New Hilux 2,4G DC 4X4 M | D6: pickup_suv | E6: PT. UT
A7: BPN | B7: KT 8621 YR | C7: Toyota All New Hilux 2,4G DC 4X4 M | D7: pickup_suv | E7: PT. UT
A8: BPN | B8: KT 8932 ZA | C8: Toyota All New Hilux 2,4G DC 4X4 M | D8: pickup_suv | E8: PT. UT
A9: BPN | B9: KT 8942 ZE | C9: Toyota All New Hilux 2,4G DC 4X4 M | D9: pickup_suv | E9: PT. UT
A10: BPN | B10: KT 1538 HC | C10: Daihatsu New Terios 1,5 R A | D10: pickup_suv | E10: PT. UT | F10: KT 1120 YR
A11: BPN | B11: KT 8926 ZK | C11: Toyota Hilux Rangga Pick Up 2,0 STD M | D11: pickup_suv | E11: PT. UT | F11: KT 8485 XB
A12: BPN | B12: KT 7233 K | C12: Isuzu NQR 71 EC E2-1 5,0 Bus | D12: bus | E12: PT. KRA
A13: BPN | B13: KT 7236 K | C13: Isuzu NQR 71 EC E2-1 5,0 Bus | D13: bus | E13: PT. KRA
A14: BPN | B14: KT 8870 YP | C14: Daihatsu Gran Max PU AC PS 1,5 FH EA | D14: pickup_suv | E14: PT. TRIATRA
A15: SANGA SANGA | B15: KT 8714 YK | C15: Toyota All New Hilux 2,4 G DC 4X4 M | D15: pickup_suv | E15: PT. TRIATRA
A16: JAKARTA | B16: B 1493 EOG | C16: Toyota Kijang Innova 2,0E A | D16: pickup_suv | E16: PT. INTERNUSA JAYARAYA ABADI
A17: JAKARTA | B17: B 2317 UKL | C17: Toyota Grand New Avanza 1,3 G M | D17: pickup_suv | E17: PT. INTERNUSA JAYARAYA ABADI
A18: JAKARTA | B18: B 2229 UOK | C18: Toyota All New Innova 2,0 G A | D18: pickup_suv | E18: PT. INTERNUSA JAYARAYA ABADI
A19: JAKARTA | B19: B 1695 EOS | C19: Toyota All New Innova 2.0 G A | D19: pickup_suv | E19: PT. INTERNUSA JAYARAYA ABADI
A20: JAKARTA | B20: B 1984 EJA | C20: Toyota Fortuner 2,7V Automatic TCN51 | D20: pickup_suv | E20: PT. INTERNUSA JAYARAYA ABADI
A21: JAKARTA | B21: B 1327 EOH | C21: Toyota Grand New Avanza 1.3 G M | D21: pickup_suv | E21: PT. NAJR
A22: SANGA SANGA | B22: KT 7564 KA | C22: Isuzu NLR 55B LX Mikrobus 2,771 (20 Seat + AC) | D22: bus | E22: PT. TRIATRA | F22: KT 7524 K
A23: SANGATTA | B23: KT 8154 YH | C23: Toyota All New Hilux 2,4E DC 4X4 M | D23: pickup_suv | E23: PT. NAJR | F23: KT 8507 NR
A24: BPN | B24: KT 8836 YQ | C24: Toyota All New Hilux 2,4 G DC 4X4 M | D24: pickup_suv | E24: PT. NAJR
A25: LOREH | B25: KT 1619 YI | C25: Toyota All New Fortuner 2,4 VRZ 4X4 A | D25: pickup_suv | E25: PT. UT
A26: LOREH | B26: KT 8526 YT | C26: Toyota All New Hilux 2,393 CC G DC 4X4 M | D26: pickup_suv | E26: PT. UT
A27: LOREH | B27: KT 8527 YT | C27: Toyota All New Hilux 2,393 CC G DC 4X4 M | D27: pickup_suv | E27: PT. UT
A28: LOREH | B28: KT 8039 YV | C28: Toyota All New Hilux 2,393 CC G DC 4X4 M | D28: pickup_suv | E28: PT. UT
A29: LOREH | B29: KT 8041 YV | C29: Toyota All New Hilux 2,393 CC G DC 4X4 M | D29: pickup_suv | E29: PT. UT
A30: LOREH | B30: KT 8042 YV | C30: Toyota All New Hilux 2,393 CC G DC 4X4 M | D30: pickup_suv | E30: PT. UT
A31: LOREH | B31: KT 8322 YV | C31: Toyota All New Hilux 2,393 CC SC 4X4 M | D31: pickup_suv | E31: PT. UT
A32: LOREH | B32: B 2468 UZT | C32: Toyota All New Innova Reborn 2,4 G M | D32: pickup_suv | E32: PT. UT
A33: LOREH | B33: KT 8417 YS | C33: Mitsubishi All New Triton 2,442 GLS DC 4X4 M | D33: pickup_suv | E33: PT. NAJR - GS
A34: LOREH | B34: KT 8036 YV | C34: Toyota All New Hilux 2,393 G DC 4X4 M | D34: pickup_suv | E34: PT. NAJR - GS
A35: MUARA LAWA | B35: KT 8475 YZ | C35: Toyota All New Hilux 2,393 CC G DC 4X4 M | D35: pickup_suv | E35: PT. UT - Damai /
... A41: MUARA LAWA | B41: KT 8307 ZF | C41: Toyota All New Hilux SC 2,4 4X4 M | D41: pickup_suv | E41: PT. UT - Damai /
A42: MUARA LAWA | B42: B 2213 UYO | C42: Toyota Innova Reborn 2,4G M | D42: pickup_suv | E42: PT. UT - Damai / | F42: B 1045 BCF
A43: MUARA LAWA | B43: DD 8468 UY | C43: Toyota All New Hilux 2,4G DC 4X4 M | D43: pickup_suv | E43: PT. UT - Damai / | F43: DD 1407 XX
A44: MUARA LAWA | B44: DD 8467 UY | C44: Toyota All New Hilux 2,4G DC 4X4 M | D44: pickup_suv | E44: PT. UT - Damai / | F44: DD 1781 XX
A45: MUARA LAWA | B45: KT 8471 ZH | C45: Toyota All New Hilux 2,4G DC 4X4 M | D45: pickup_suv | E45: PT. UT - Damai / | F45: KT 8367 WE
...

Sheet SETUP AWAL ITEM
A1: Plat Nomor (otomatis) | B1: Nama Item (otomatis) | C1: Kapan Terakhir Diganti (Tanggal) | D1: KM Saat Diganti (opsional)
A2: =IF('DATA UNIT'!$B2="","",'DATA UNIT'!$B2) -> B 2444 UIL | B2: =IF($A2="","",INDEX(PlanningItemsList,1)) -> PM Check / Reguler Services
A3: =IF('DATA UNIT'!$B2="","",'DATA UNIT'!$B2) -> B 2444 UIL | B3: =IF($A3="","",INDEX(PlanningItemsList,2)) -> Service A
A4: =IF('DATA UNIT'!$B2="","",'DATA UNIT'!$B2) -> B 2444 UIL | B4: =IF($A4="","",INDEX(PlanningItemsList,3)) -> Service B
A5: =IF('DATA UNIT'!$B2="","",'DATA UNIT'!$B2) -> B 2444 UIL | B5: =IF($A5="","",INDEX(PlanningItemsList,4)) -> Brake Pad
A6: =IF('DATA UNIT'!$B2="","",'DATA UNIT'!$B2) -> B 2444 UIL | B6: =IF($A6="","",INDEX(PlanningItemsList,5)) -> Brake Shoe
A7: =IF('DATA UNIT'!$B2="","",'DATA UNIT'!$B2) -> B 2444 UIL | B7: =IF($A7="","",INDEX(PlanningItemsList,6)) -> Accu
A8: =IF('DATA UNIT'!$B2="","",'DATA UNIT'!$B2) -> B 2444 UIL | B8: =IF($A8="","",INDEX(PlanningItemsList,7)) -> Kampas Kopling Set
A9: =IF('DATA UNIT'!$B2="","",'DATA UNIT'!$B2) -> B 2444 UIL | B9: =IF($A9="","",INDEX(PlanningItemsList,8)) -> Wiper Blade
A10: =IF('DATA UNIT'!$B2="","",'DATA UNIT'!$B2) -> B 2444 UIL | B10: =IF($A10="","",INDEX(PlanningItemsList,9)) -> Ban Depan
A11: =IF('DATA UNIT'!$B2="","",'DATA UNIT'!$B2) -> B 2444 UIL | B11: =IF($A11="","",INDEX(PlanningItemsList,10)) -> Ban Belakang
A12: =IF('DATA UNIT'!$B2="","",'DATA UNIT'!$B2) -> B 2444 UIL | B12: =IF($A12="","",INDEX(PlanningItemsList,11)) -> Ban Serep
A13: =IF('DATA UNIT'!$B2="","",'DATA UNIT'!$B2) -> B 2444 UIL | B13: =IF($A13="","",INDEX(PlanningItemsList,12)) -> Greasing
A14: =IF('DATA UNIT'!$B2="","",'DATA UNIT'!$B2) -> B 2444 UIL | B14: =IF($A14="","",INDEX(PlanningItemsList,13)) -> V-Belt
A15: =IF('DATA UNIT'!$B2="","",'DATA UNIT'!$B2) -> B 2444 UIL | B15: =IF($A15="","",INDEX(PlanningItemsList,14)) -> Sarung Jok
A16: =IF('DATA UNIT'!$B2="","",'DATA UNIT'!$B2) -> B 2444 UIL | B16: =IF($A16="","",INDEX(PlanningItemsList,15)) -> Karpet Karet
A17: =IF('DATA UNIT'!$B2="","",'DATA UNIT'!$B2) -> B 2444 UIL | B17: =IF($A17="","",INDEX(PlanningItemsList,16)) -> Karpet Dasar
A18: =IF('DATA UNIT'!$B2="","",'DATA UNIT'!$B2) -> B 2444 UIL | B18: =IF($A18="","",INDEX(PlanningItemsList,17)) -> Flushing Radiator
A19: =IF('DATA UNIT'!$B2="","",'DATA UNIT'!$B2) -> B 2444 UIL | B19: =IF($A19="","",INDEX(PlanningItemsList,18)) -> Flushing Steering
A20: =IF('DATA UNIT'!$B2="","",'DATA UNIT'!$B2) -> B 2444 UIL | B20: =IF($A20="","",INDEX(PlanningItemsList,19)) -> Flushing Injector
A21: =IF('DATA UNIT'!$B2="","",'DATA UNIT'!$B2) -> B 2444 UIL | B21: =IF($A21="","",INDEX(PlanningItemsList,20)) -> Flushing Rem
A22: =IF('DATA UNIT'!$B3="","",'DATA UNIT'!$B3) -> B 2533 UIY | B22: =IF($A22="","",INDEX(PlanningItemsList,1)) -> PM Check / Reguler Services
A23: =IF('DATA UNIT'!$B3="","",'DATA UNIT'!$B3) -> B 2533 UIY | B23: =IF($A23="","",INDEX(PlanningItemsList,2)) -> Service A
A24: =IF('DATA UNIT'!$B3="","",'DATA UNIT'!$B3) -> B 2533 UIY | B24: =IF($A24="","",INDEX(PlanningItemsList,3)) -> Service B
A25: =IF('DATA UNIT'!$B3="","",'DATA UNIT'!$B3) -> B 2533 UIY | B25: =IF($A25="","",INDEX(PlanningItemsList,4)) -> Brake Pad
A26: =IF('DATA UNIT'!$B3="","",'DATA UNIT'!$B3) -> B 2533 UIY | B26: =IF($A26="","",INDEX(PlanningItemsList,5)) -> Brake Shoe
A27: =IF('DATA UNIT'!$B3="","",'DATA UNIT'!$B3) -> B 2533 UIY | B27: =IF($A27="","",INDEX(PlanningItemsList,6)) -> Accu
A28: =IF('DATA UNIT'!$B3="","",'DATA UNIT'!$B3) -> B 2533 UIY | B28: =IF($A28="","",INDEX(PlanningItemsList,7)) -> Kampas Kopling Set
A29: =IF('DATA UNIT'!$B3="","",'DATA UNIT'!$B3) -> B 2533 UIY | B29: =IF($A29="","",INDEX(PlanningItemsList,8)) -> Wiper Blade
A30: =IF('DATA UNIT'!$B3="","",'DATA UNIT'!$B3) -> B 2533 UIY | B30: =IF($A30="","",INDEX(PlanningItemsList,9)) -> Ban Depan
A31: =IF('DATA UNIT'!$B3="","",'DATA UNIT'!$B3) -> B 2533 UIY | B31: =IF($A31="","",INDEX(PlanningItemsList,10)) -> Ban Belakang
A32: =IF('DATA UNIT'!$B3="","",'DATA UNIT'!$B3) -> B 2533 UIY | B32: =IF($A32="","",INDEX(PlanningItemsList,11)) -> Ban Serep
A33: =IF('DATA UNIT'!$B3="","",'DATA UNIT'!$B3) -> B 2533 UIY | B33: =IF($A33="","",INDEX(PlanningItemsList,12)) -> Greasing
A34: =IF('DATA UNIT'!$B3="","",'DATA UNIT'!$B3) -> B 2533 UIY | B34: =IF($A34="","",INDEX(PlanningItemsList,13)) -> V-Belt
A35: =IF('DATA UNIT'!$B3="","",'DATA UNIT'!$B3) -> B 2533 UIY | B35: =IF($A35="","",INDEX(PlanningItemsList,14)) -> Sarung Jok
A36: =IF('DATA UNIT'!$B3="","",'DATA UNIT'!$B3) -> B 2533 UIY | B36: =IF($A36="","",INDEX(PlanningItemsList,15)) -> Karpet Karet
A37: =IF('DATA UNIT'!$B3="","",'DATA UNIT'!$B3) -> B 2533 UIY | B37: =IF($A37="","",INDEX(PlanningItemsList,16)) -> Karpet Dasar
A38: =IF('DATA UNIT'!$B3="","",'DATA UNIT'!$B3) -> B 2533 UIY | B38: =IF($A38="","",INDEX(PlanningItemsList,17)) -> Flushing Radiator
A39: =IF('DATA UNIT'!$B3="","",'DATA UNIT'!$B3) -> B 2533 UIY | B39: =IF($A39="","",INDEX(PlanningItemsList,18)) -> Flushing Steering
A40: =IF('DATA UNIT'!$B3="","",'DATA UNIT'!$B3) -> B 2533 UIY | B40: =IF($A40="","",INDEX(PlanningItemsList,19)) -> Flushing Injector
...
